{"name": "test_one", "status": "failed", "statusDetails": {"message": "AssertionError: assert 'h' in 'x'", "trace": "self = <unit.test_pytest.TestClass object at 0x000001EA9870A550>\n\n    def test_one(self):\n        x = \"this\"\n>       assert \"h\" in \"x\"\nE       AssertionError: assert 'h' in 'x'\n\nunit\\test_pytest.py:32: AssertionError"}, "attachments": [{"name": "stdout", "source": "18d65d02-8d21-4a3c-9e71-08ee927b8f61-attachment.txt", "type": "text/plain"}], "start": 1583118100915, "stop": 1583118100918, "uuid": "bd5329c3-9112-4c17-9b60-881e2f7385e2", "historyId": "035252782fbb6a63cb4e3bc8545d7de3", "testCaseId": "ecf849f7a467d18afdb7a07cbf92fe91", "fullName": "unit.test_pytest.TestClass#test_one", "labels": [{"name": "parentSuite", "value": "unit"}, {"name": "suite", "value": "test_pytest"}, {"name": "subSuite", "value": "TestClass"}, {"name": "host", "value": "DESKTOP-2P3JG1L"}, {"name": "thread", "value": "6744-MainThread"}, {"name": "framework", "value": "pytest"}, {"name": "language", "value": "cpython3"}, {"name": "package", "value": "unit.test_pytest"}]}